<sdf version='1.6'>
  <world name='default'>
    <light name='sun' type='directional'>
      <cast_shadows>1</cast_shadows>
      <pose frame=''>0 0 15 0 -0 0</pose>
      <diffuse>1 1 1 1</diffuse>
      <specular>0.1 0.1 0.1 1</specular>
      <attenuation>
        <range>1000</range>
        <constant>0.9</constant>
        <linear>0.01</linear>
        <quadratic>0.001</quadratic>
      </attenuation>
      <direction>-0.5 0.5 -1</direction>
    </light>
    <model name='ground_plane'>
      <static>1</static>
      <link name='link'>
        <collision name='collision'>
          <geometry>
            <plane>
              <normal>0 0 1</normal>
              <size>100 100</size>
            </plane>
          </geometry>
          <surface>
            <friction>
              <ode>
                <mu>100</mu>
                <mu2>50</mu2>
              </ode>
              <torsional>
                <ode/>
              </torsional>
            </friction>
            <contact>
              <ode/>
            </contact>
            <bounce/>
          </surface>
          <max_contacts>10</max_contacts>
        </collision>
        <visual name='visual'>
          <transparency>1</transparency>
          <cast_shadows>0</cast_shadows>
          <geometry>
            <plane>
              <normal>0 0 1</normal>
              <size>100 100</size>
            </plane>
          </geometry>
          <material>
            <script>
              <uri>file://media/materials/scripts/gazebo.material</uri>
              <name>Gazebo/Grey</name>
            </script>
          </material>
        </visual>
        <self_collide>0</self_collide>
        <kinematic>0</kinematic>
        <gravity>1</gravity>
      </link>
    </model>
    <gravity>0 0 -9.8</gravity>
    <magnetic_field>6e-06 2.3e-05 -4.2e-05</magnetic_field>
    <atmosphere type='adiabatic'/>
    <physics name='default_physics' default='0' type='ode'>
      <max_step_size>0.001</max_step_size>
      <real_time_factor>1</real_time_factor>
      <real_time_update_rate>1000</real_time_update_rate>
    </physics>
    <scene>
      <ambient>0.4 0.4 0.4 1</ambient>
      <background>0.7 0.7 0.7 1</background>
      <shadows>1</shadows>
    </scene>
    <spherical_coordinates>
      <surface_model>EARTH_WGS84</surface_model>
      <latitude_deg>0</latitude_deg>
      <longitude_deg>0</longitude_deg>
      <elevation>0</elevation>
      <heading_deg>0</heading_deg>
    </spherical_coordinates>
    <state world_name='default'>
      <sim_time>1922 350000000</sim_time>
      <real_time>31 337658836</real_time>
      <wall_time>1545454104 345669580</wall_time>
      <iterations>31171</iterations>
      <model name='Parking2'>
        <pose frame=''>-2.61849 -1.94375 0 0 -0 0</pose>
        <scale>1 1 1</scale>
        <model name='Construction Barrel_1'>
          <pose frame=''>-8.40718 6.89696 0 0 -0 0</pose>
          <scale>1 1 1</scale>
          <link name='link'>
            <pose frame=''>-8.40718 6.89696 0 0 -0 0</pose>
            <velocity>0 0 0 0 -0 0</velocity>
            <acceleration>0 0 0 0 -0 0</acceleration>
            <wrench>0 0 0 0 -0 0</wrench>
          </link>
        </model>
        <model name='Construction Cone_clone_0'>
          <pose frame=''>-10.3975 5.89697 0 0 -0 0</pose>
          <scale>1 1 1</scale>
          <link name='link'>
            <pose frame=''>-10.3975 5.89697 0 0 -0 0</pose>
            <velocity>0 0 0 0 -0 0</velocity>
            <acceleration>0 0 0 0 -0 0</acceleration>
            <wrench>0 0 0 0 -0 0</wrench>
          </link>
        </model>
        <model name='Dumpster'>
          <pose frame=''>-6.34807 6.89696 0 0 -0 0</pose>
          <scale>1 1 1</scale>
          <link name='link'>
            <pose frame=''>-6.34807 6.89696 0 0 -0 0</pose>
            <velocity>0 0 0 0 -0 0</velocity>
            <acceleration>0 0 0 0 -0 0</acceleration>
            <wrench>0 0 0 0 -0 0</wrench>
          </link>
        </model>
        <model name='asphalt_plane'>
          <pose frame=''>-2.91407 -1.06086 0 0 -0 0</pose>
          <scale>1 1 1</scale>
          <link name='link'>
            <pose frame=''>-2.91407 -1.06086 0 0 -0 0</pose>
            <velocity>0 0 0 0 -0 0</velocity>
            <acceleration>0 0 0 0 -0 0</acceleration>
            <wrench>0 0 0 0 -0 0</wrench>
          </link>
        </model>
        <model name='grey_wall'>
          <pose frame=''>-9.18405 -10.9654 0 0 -0 0</pose>
          <scale>1 1 1</scale>
          <link name='link'>
            <pose frame=''>-9.18405 -10.9654 1.4 0 -0 0</pose>
            <velocity>0 0 0 0 -0 0</velocity>
            <acceleration>0 0 0 0 -0 0</acceleration>
            <wrench>0 0 0 0 -0 0</wrench>
          </link>
        </model>
        <model name='grey_wall_clone'>
          <pose frame=''>-1.69945 -10.9575 0 0 -0 0</pose>
          <scale>1 1 1</scale>
          <link name='link'>
            <pose frame=''>-1.69945 -10.9575 1.4 0 -0 0</pose>
            <velocity>0 0 0 0 -0 0</velocity>
            <acceleration>0 0 0 0 -0 0</acceleration>
            <wrench>0 0 0 0 -0 0</wrench>
          </link>
        </model>
        <model name='grey_wall_clone_0'>
          <pose frame=''>-12.828 -7.24643 0 0 0 -1.57377</pose>
          <scale>1 1 1</scale>
          <link name='link'>
            <pose frame=''>-12.828 -7.24643 1.4 0 0 -1.57377</pose>
            <velocity>0 0 0 0 -0 0</velocity>
            <acceleration>0 0 0 0 -0 0</acceleration>
            <wrench>0 0 0 0 -0 0</wrench>
          </link>
        </model>
        <model name='grey_wall_clone_0_clone'>
          <pose frame=''>-12.7993 0.23144 0 0 0 -1.57377</pose>
          <scale>1 1 1</scale>
          <link name='link'>
            <pose frame=''>-12.7993 0.23144 1.4 0 0 -1.57377</pose>
            <velocity>0 0 0 0 -0 0</velocity>
            <acceleration>0 0 0 0 -0 0</acceleration>
            <wrench>0 0 0 0 -0 0</wrench>
          </link>
        </model>
        <model name='grey_wall_clone_0_clone_clone'>
          <pose frame=''>-12.8123 5.22817 0 0 0 -1.57377</pose>
          <scale>1 1 1</scale>
          <link name='link'>
            <pose frame=''>-12.8123 5.22817 1.4 0 0 -1.57377</pose>
            <velocity>0 0 0 0 -0 0</velocity>
            <acceleration>0 0 0 0 -0 0</acceleration>
            <wrench>0 0 0 0 -0 0</wrench>
          </link>
        </model>
        <model name='grey_wall_clone_1'>
          <pose frame=''>-9.1363 8.84615 0 0 -0 0</pose>
          <scale>1 1 1</scale>
          <link name='link'>
            <pose frame=''>-9.1363 8.84615 1.4 0 -0 0</pose>
            <velocity>0 0 0 0 -0 0</velocity>
            <acceleration>0 0 0 0 -0 0</acceleration>
            <wrench>0 0 0 0 -0 0</wrench>
          </link>
        </model>
        <model name='grey_wall_clone_1_clone'>
          <pose frame=''>-1.64495 8.82875 0 0 -0 0</pose>
          <scale>1 1 1</scale>
          <link name='link'>
            <pose frame=''>-1.64495 8.82875 1.4 0 -0 0</pose>
            <velocity>0 0 0 0 -0 0</velocity>
            <acceleration>0 0 0 0 -0 0</acceleration>
            <wrench>0 0 0 0 -0 0</wrench>
          </link>
        </model>
        <model name='oak_tree'>
          <pose frame=''>0.40504 -9.11979 0 0 0 -2.86719</pose>
          <scale>1 1 1</scale>
          <link name='link'>
            <pose frame=''>0.40504 -9.11979 0 0 0 -2.86719</pose>
            <velocity>0 0 0 0 -0 0</velocity>
            <acceleration>0 0 0 0 -0 0</acceleration>
            <wrench>0 0 0 0 -0 0</wrench>
          </link>
        </model>
        <model name='pickup'>
          <pose frame=''>-8.87088 -7.10303 0 0 -0 0</pose>
          <scale>1 1 1</scale>
          <link name='link'>
            <pose frame=''>-8.87088 -7.10303 0 0 -0 0</pose>
            <velocity>0 0 0 0 -0 0</velocity>
            <acceleration>0 0 0 0 -0 0</acceleration>
            <wrench>0 0 0 0 -0 0</wrench>
          </link>
        </model>
        <model name='pine_tree'>
          <pose frame=''>-2.3818 7.37196 0 0 -0 0</pose>
          <scale>1 1 1</scale>
          <link name='link'>
            <pose frame=''>-2.3818 7.37196 0 0 -0 0</pose>
            <velocity>0 0 0 0 -0 0</velocity>
            <acceleration>0 0 0 0 -0 0</acceleration>
            <wrench>0 0 0 0 -0 0</wrench>
          </link>
        </model>
        <model name='pine_tree_4'>
          <pose frame=''>5.12912 7.89696 0 0 -0 0</pose>
          <scale>1 1 1</scale>
          <link name='link'>
            <pose frame=''>5.12912 7.89696 0 0 -0 0</pose>
            <velocity>0 0 0 0 -0 0</velocity>
            <acceleration>0 0 0 0 -0 0</acceleration>
            <wrench>0 0 0 0 -0 0</wrench>
          </link>
        </model>
        <model name='polaris_ranger_xp900'>
          <pose frame=''>-9.87088 1.89696 0 0 -0 0</pose>
          <scale>1 1 1</scale>
          <link name='FNR_switch'>
            <pose frame=''>-9.33088 1.99696 1.15 0 0.25 0</pose>
            <velocity>0 0 0 0 -0 0</velocity>
            <acceleration>0 0 0 0 -0 0</acceleration>
            <wrench>0 0 0 0 -0 0</wrench>
          </link>
          <link name='brake_pedal'>
            <pose frame=''>-9.23088 2.16696 0.58 0 -0 0</pose>
            <velocity>0 0 0 0 -0 0</velocity>
            <acceleration>0 0 0 0 -0 0</acceleration>
            <wrench>0 0 0 0 -0 0</wrench>
          </link>
          <link name='chassis'>
            <pose frame=''>-9.87088 1.89696 0 0 -0 0</pose>
            <velocity>0 0 0 0 -0 0</velocity>
            <acceleration>0 0 0 0 -0 0</acceleration>
            <wrench>0 0 0 0 -0 0</wrench>
          </link>
          <link name='front_left_wheel'>
            <pose frame=''>-8.66865 2.61258 0.34697 -1.52 0 0</pose>
            <velocity>0 0 0 0 -0 0</velocity>
            <acceleration>0 0 0 0 -0 0</acceleration>
            <wrench>0 0 0 0 -0 0</wrench>
          </link>
          <link name='front_left_wheel_steering_block'>
            <pose frame=''>-8.66865 2.39696 0.35515 1.5708 -0 0</pose>
            <velocity>0 0 0 0 -0 0</velocity>
            <acceleration>0 0 0 0 -0 0</acceleration>
            <wrench>0 0 0 0 -0 0</wrench>
          </link>
          <link name='front_right_wheel'>
            <pose frame=''>-8.66865 1.18134 0.34697 1.52 -0 0</pose>
            <velocity>0 0 0 0 -0 0</velocity>
            <acceleration>0 0 0 0 -0 0</acceleration>
            <wrench>0 0 0 0 -0 0</wrench>
          </link>
          <link name='front_right_wheel_steering_block'>
            <pose frame=''>-8.66865 1.39696 0.35515 1.5708 -0 0</pose>
            <velocity>0 0 0 0 -0 0</velocity>
            <acceleration>0 0 0 0 -0 0</acceleration>
            <wrench>0 0 0 0 -0 0</wrench>
          </link>
          <link name='gas_pedal'>
            <pose frame=''>-9.24088 1.99696 0.58 0 -0 0</pose>
            <velocity>0 0 0 0 -0 0</velocity>
            <acceleration>0 0 0 0 -0 0</acceleration>
            <wrench>0 0 0 0 -0 0</wrench>
          </link>
          <link name='hand_brake'>
            <pose frame=''>-9.34088 2.10196 1.05 0 -0 0</pose>
            <velocity>0 0 0 0 -0 0</velocity>
            <acceleration>0 0 0 0 -0 0</acceleration>
            <wrench>0 0 0 0 -0 0</wrench>
          </link>
          <link name='rear_left_wheel'>
            <pose frame=''>-10.8646 2.61258 0.34697 -1.52 0 0</pose>
            <velocity>0 0 0 0 -0 0</velocity>
            <acceleration>0 0 0 0 -0 0</acceleration>
            <wrench>0 0 0 0 -0 0</wrench>
          </link>
          <link name='rear_right_wheel'>
            <pose frame=''>-10.8646 1.18134 0.34697 1.52 -0 0</pose>
            <velocity>0 0 0 0 -0 0</velocity>
            <acceleration>0 0 0 0 -0 0</acceleration>
            <wrench>0 0 0 0 -0 0</wrench>
          </link>
          <link name='steering_wheel'>
            <pose frame=''>-9.45088 2.35696 1.2 0 -0.87 0</pose>
            <velocity>0 0 0 0 -0 0</velocity>
            <acceleration>0 0 0 0 -0 0</acceleration>
            <wrench>0 0 0 0 -0 0</wrench>
          </link>
        </model>
      </model>
      <model name='ground_plane'>
        <pose frame=''>0 0 0 0 -0 0</pose>
        <scale>1 1 1</scale>
        <link name='link'>
          <pose frame=''>0 0 0 0 -0 0</pose>
          <velocity>0 0 0 0 -0 0</velocity>
          <acceleration>0 0 0 0 -0 0</acceleration>
          <wrench>0 0 0 0 -0 0</wrench>
        </link>
      </model>
      <light name='sun'>
        <pose frame=''>0 0 15 0 -0 0</pose>
      </light>
    </state>
    <gui fullscreen='0'>
      <camera name='user_camera'>
        <pose frame=''>26.2317 1.18897 31.1041 -0.004249 0.620777 -2.87409</pose>
        <view_controller>orbit</view_controller>
        <projection_type>perspective</projection_type>
      </camera>
    </gui>
    <model name='Parking2'>
      <model name='Construction Barrel_1'>
        <static>1</static>
        <link name='link'>
          <inertial>
            <pose frame=''>0 0 0.4 0 -0 0</pose>
            <mass>500</mass>
            <inertia>
              <ixx>51.2096</ixx>
              <iyy>51.2096</iyy>
              <izz>25</izz>
              <ixy>0</ixy>
              <ixz>0</ixz>
              <iyz>0</iyz>
            </inertia>
          </inertial>
          <collision name='collision'>
            <geometry>
              <mesh>
                <uri>model://construction_barrel/meshes/construction_barrel.dae</uri>
              </mesh>
            </geometry>
            <max_contacts>10</max_contacts>
            <surface>
              <contact>
                <ode/>
              </contact>
              <bounce/>
              <friction>
                <torsional>
                  <ode/>
                </torsional>
                <ode/>
              </friction>
            </surface>
          </collision>
          <visual name='visual'>
            <geometry>
              <mesh>
                <uri>model://construction_barrel/meshes/construction_barrel.dae</uri>
              </mesh>
            </geometry>
          </visual>
          <self_collide>0</self_collide>
          <kinematic>0</kinematic>
          <gravity>1</gravity>
        </link>
        <pose frame=''>-5.78869 8.84071 0 0 -0 0</pose>
      </model>
      <model name='Construction Cone_clone_0'>
        <static>1</static>
        <link name='link'>
          <collision name='collision'>
            <geometry>
              <mesh>
                <scale>10 10 10</scale>
                <uri>model://construction_cone/meshes/construction_cone.dae</uri>
              </mesh>
            </geometry>
            <max_contacts>10</max_contacts>
            <surface>
              <contact>
                <ode/>
              </contact>
              <bounce/>
              <friction>
                <torsional>
                  <ode/>
                </torsional>
                <ode/>
              </friction>
            </surface>
          </collision>
          <visual name='visual'>
            <geometry>
              <mesh>
                <scale>10 10 10</scale>
                <uri>model://construction_cone/meshes/construction_cone.dae</uri>
              </mesh>
            </geometry>
          </visual>
          <self_collide>0</self_collide>
          <kinematic>0</kinematic>
          <gravity>1</gravity>
        </link>
        <pose frame=''>-7.77904 7.84072 0 0 -0 0</pose>
      </model>
      <model name='Dumpster'>
        <link name='link'>
          <collision name='collision'>
            <geometry>
              <mesh>
                <uri>model://dumpster/meshes/dumpster.dae</uri>
              </mesh>
            </geometry>
            <max_contacts>10</max_contacts>
            <surface>
              <contact>
                <ode/>
              </contact>
              <bounce/>
              <friction>
                <torsional>
                  <ode/>
                </torsional>
                <ode/>
              </friction>
            </surface>
          </collision>
          <visual name='visual'>
            <geometry>
              <mesh>
                <uri>model://dumpster/meshes/dumpster.dae</uri>
              </mesh>
            </geometry>
            <material>
              <script>
                <uri>model://dumpster/materials/scripts</uri>
                <uri>model://dumpster/materials/textures</uri>
                <name>Dumpster/Diffuse</name>
              </script>
            </material>
          </visual>
          <self_collide>0</self_collide>
          <inertial>
            <inertia>
              <ixx>1</ixx>
              <ixy>0</ixy>
              <ixz>0</ixz>
              <iyy>1</iyy>
              <iyz>0</iyz>
              <izz>1</izz>
            </inertia>
            <mass>1</mass>
          </inertial>
          <kinematic>0</kinematic>
          <gravity>1</gravity>
        </link>
        <pose frame=''>-3.72958 8.84071 0 0 -0 0</pose>
      </model>
      <model name='asphalt_plane'>
        <static>1</static>
        <link name='link'>
          <collision name='collision'>
            <geometry>
              <box>
                <size>20 20 0.1</size>
              </box>
            </geometry>
            <max_contacts>10</max_contacts>
            <surface>
              <contact>
                <ode/>
              </contact>
              <bounce/>
              <friction>
                <torsional>
                  <ode/>
                </torsional>
                <ode/>
              </friction>
            </surface>
          </collision>
          <visual name='visual'>
            <cast_shadows>0</cast_shadows>
            <geometry>
              <box>
                <size>20 20 0.1</size>
              </box>
            </geometry>
            <material>
              <script>
                <uri>model://asphalt_plane/materials/scripts</uri>
                <uri>model://asphalt_plane/materials/textures</uri>
                <name>vrc/asphalt</name>
              </script>
            </material>
          </visual>
          <self_collide>0</self_collide>
          <kinematic>0</kinematic>
          <gravity>1</gravity>
        </link>
        <pose frame=''>-0.295584 0.882891 0 0 -0 0</pose>
      </model>
      <model name='grey_wall'>
        <static>1</static>
        <link name='link'>
          <pose frame=''>0 0 1.4 0 -0 0</pose>
          <collision name='collision'>
            <geometry>
              <box>
                <size>7.5 0.2 2.8</size>
              </box>
            </geometry>
            <max_contacts>10</max_contacts>
            <surface>
              <contact>
                <ode/>
              </contact>
              <bounce/>
              <friction>
                <torsional>
                  <ode/>
                </torsional>
                <ode/>
              </friction>
            </surface>
          </collision>
          <visual name='visual'>
            <cast_shadows>0</cast_shadows>
            <geometry>
              <box>
                <size>7.5 0.2 2.8</size>
              </box>
            </geometry>
            <material>
              <script>
                <uri>model://grey_wall/materials/scripts</uri>
                <uri>model://grey_wall/materials/textures</uri>
                <name>vrc/grey_wall</name>
              </script>
            </material>
          </visual>
          <self_collide>0</self_collide>
          <kinematic>0</kinematic>
          <gravity>1</gravity>
        </link>
        <pose frame=''>-6.56556 -9.02161 0 0 -0 0</pose>
      </model>
      <model name='grey_wall_clone'>
        <static>1</static>
        <link name='link'>
          <pose frame=''>0 0 1.4 0 -0 0</pose>
          <collision name='collision'>
            <geometry>
              <box>
                <size>7.5 0.2 2.8</size>
              </box>
            </geometry>
            <max_contacts>10</max_contacts>
            <surface>
              <contact>
                <ode/>
              </contact>
              <bounce/>
              <friction>
                <torsional>
                  <ode/>
                </torsional>
                <ode/>
              </friction>
            </surface>
          </collision>
          <visual name='visual'>
            <cast_shadows>0</cast_shadows>
            <geometry>
              <box>
                <size>7.5 0.2 2.8</size>
              </box>
            </geometry>
            <material>
              <script>
                <uri>model://grey_wall/materials/scripts</uri>
                <uri>model://grey_wall/materials/textures</uri>
                <name>vrc/grey_wall</name>
              </script>
            </material>
          </visual>
          <self_collide>0</self_collide>
          <kinematic>0</kinematic>
          <gravity>1</gravity>
        </link>
        <pose frame=''>0.919044 -9.0138 0 0 -0 0</pose>
      </model>
      <model name='grey_wall_clone_0'>
        <static>1</static>
        <link name='link'>
          <pose frame=''>0 0 1.4 0 -0 0</pose>
          <collision name='collision'>
            <geometry>
              <box>
                <size>7.5 0.2 2.8</size>
              </box>
            </geometry>
            <max_contacts>10</max_contacts>
            <surface>
              <contact>
                <ode/>
              </contact>
              <bounce/>
              <friction>
                <torsional>
                  <ode/>
                </torsional>
                <ode/>
              </friction>
            </surface>
          </collision>
          <visual name='visual'>
            <cast_shadows>0</cast_shadows>
            <geometry>
              <box>
                <size>7.5 0.2 2.8</size>
              </box>
            </geometry>
            <material>
              <script>
                <uri>model://grey_wall/materials/scripts</uri>
                <uri>model://grey_wall/materials/textures</uri>
                <name>vrc/grey_wall</name>
              </script>
            </material>
          </visual>
          <self_collide>0</self_collide>
          <kinematic>0</kinematic>
          <gravity>1</gravity>
        </link>
        <pose frame=''>-10.2095 -5.30268 0 0 0 -1.57377</pose>
      </model>
      <model name='grey_wall_clone_0_clone'>
        <static>1</static>
        <link name='link'>
          <pose frame=''>0 0 1.4 0 -0 0</pose>
          <collision name='collision'>
            <geometry>
              <box>
                <size>7.5 0.2 2.8</size>
              </box>
            </geometry>
            <max_contacts>10</max_contacts>
            <surface>
              <contact>
                <ode/>
              </contact>
              <bounce/>
              <friction>
                <torsional>
                  <ode/>
                </torsional>
                <ode/>
              </friction>
            </surface>
          </collision>
          <visual name='visual'>
            <cast_shadows>0</cast_shadows>
            <geometry>
              <box>
                <size>7.5 0.2 2.8</size>
              </box>
            </geometry>
            <material>
              <script>
                <uri>model://grey_wall/materials/scripts</uri>
                <uri>model://grey_wall/materials/textures</uri>
                <name>vrc/grey_wall</name>
              </script>
            </material>
          </visual>
          <self_collide>0</self_collide>
          <kinematic>0</kinematic>
          <gravity>1</gravity>
        </link>
        <pose frame=''>-10.1808 2.17519 0 0 0 -1.57377</pose>
      </model>
      <model name='grey_wall_clone_0_clone_clone'>
        <static>1</static>
        <link name='link'>
          <pose frame=''>0 0 1.4 0 -0 0</pose>
          <collision name='collision'>
            <geometry>
              <box>
                <size>7.5 0.2 2.8</size>
              </box>
            </geometry>
            <max_contacts>10</max_contacts>
            <surface>
              <contact>
                <ode/>
              </contact>
              <bounce/>
              <friction>
                <torsional>
                  <ode/>
                </torsional>
                <ode/>
              </friction>
            </surface>
          </collision>
          <visual name='visual'>
            <cast_shadows>0</cast_shadows>
            <geometry>
              <box>
                <size>7.5 0.2 2.8</size>
              </box>
            </geometry>
            <material>
              <script>
                <uri>model://grey_wall/materials/scripts</uri>
                <uri>model://grey_wall/materials/textures</uri>
                <name>vrc/grey_wall</name>
              </script>
            </material>
          </visual>
          <self_collide>0</self_collide>
          <kinematic>0</kinematic>
          <gravity>1</gravity>
        </link>
        <pose frame=''>-10.1938 7.17192 0 0 0 -1.57377</pose>
      </model>
      <model name='grey_wall_clone_1'>
        <static>1</static>
        <link name='link'>
          <pose frame=''>0 0 1.4 0 -0 0</pose>
          <collision name='collision'>
            <geometry>
              <box>
                <size>7.5 0.2 2.8</size>
              </box>
            </geometry>
            <max_contacts>10</max_contacts>
            <surface>
              <contact>
                <ode/>
              </contact>
              <bounce/>
              <friction>
                <torsional>
                  <ode/>
                </torsional>
                <ode/>
              </friction>
            </surface>
          </collision>
          <visual name='visual'>
            <cast_shadows>0</cast_shadows>
            <geometry>
              <box>
                <size>7.5 0.2 2.8</size>
              </box>
            </geometry>
            <material>
              <script>
                <uri>model://grey_wall/materials/scripts</uri>
                <uri>model://grey_wall/materials/textures</uri>
                <name>vrc/grey_wall</name>
              </script>
            </material>
          </visual>
          <self_collide>0</self_collide>
          <kinematic>0</kinematic>
          <gravity>1</gravity>
        </link>
        <pose frame=''>-6.51781 10.7899 0 0 -0 0</pose>
      </model>
      <model name='grey_wall_clone_1_clone'>
        <static>1</static>
        <link name='link'>
          <pose frame=''>0 0 1.4 0 -0 0</pose>
          <collision name='collision'>
            <geometry>
              <box>
                <size>7.5 0.2 2.8</size>
              </box>
            </geometry>
            <max_contacts>10</max_contacts>
            <surface>
              <contact>
                <ode/>
              </contact>
              <bounce/>
              <friction>
                <torsional>
                  <ode/>
                </torsional>
                <ode/>
              </friction>
            </surface>
          </collision>
          <visual name='visual'>
            <cast_shadows>0</cast_shadows>
            <geometry>
              <box>
                <size>7.5 0.2 2.8</size>
              </box>
            </geometry>
            <material>
              <script>
                <uri>model://grey_wall/materials/scripts</uri>
                <uri>model://grey_wall/materials/textures</uri>
                <name>vrc/grey_wall</name>
              </script>
            </material>
          </visual>
          <self_collide>0</self_collide>
          <kinematic>0</kinematic>
          <gravity>1</gravity>
        </link>
        <pose frame=''>0.97354 10.7725 0 0 -0 0</pose>
      </model>
      <model name='oak_tree'>
        <static>1</static>
        <link name='link'>
          <collision name='collision'>
            <geometry>
              <mesh>
                <uri>model://oak_tree/meshes/oak_tree.dae</uri>
              </mesh>
            </geometry>
            <max_contacts>10</max_contacts>
            <surface>
              <contact>
                <ode/>
              </contact>
              <bounce/>
              <friction>
                <torsional>
                  <ode/>
                </torsional>
                <ode/>
              </friction>
            </surface>
          </collision>
          <visual name='branch'>
            <geometry>
              <mesh>
                <uri>model://oak_tree/meshes/oak_tree.dae</uri>
                <submesh>
                  <name>Branch</name>
                </submesh>
              </mesh>
            </geometry>
            <material>
              <script>
                <uri>model://oak_tree/materials/scripts/</uri>
                <uri>model://oak_tree/materials/textures/</uri>
                <name>OakTree/Branch</name>
              </script>
            </material>
          </visual>
          <visual name='bark'>
            <geometry>
              <mesh>
                <uri>model://oak_tree/meshes/oak_tree.dae</uri>
                <submesh>
                  <name>Bark</name>
                </submesh>
              </mesh>
            </geometry>
            <material>
              <script>
                <uri>model://oak_tree/materials/scripts/</uri>
                <uri>model://oak_tree/materials/textures/</uri>
                <name>OakTree/Bark</name>
              </script>
            </material>
          </visual>
          <self_collide>0</self_collide>
          <kinematic>0</kinematic>
          <gravity>1</gravity>
        </link>
        <pose frame=''>3.02353 -7.17604 0 0 0 -2.86719</pose>
      </model>
      <model name='pickup'>
        <static>1</static>
        <link name='link'>
          <collision name='collision'>
            <pose frame=''>0 0 0 0 0 -1.5708</pose>
            <geometry>
              <mesh>
                <uri>model://pickup/meshes/pickup.dae</uri>
              </mesh>
            </geometry>
            <max_contacts>10</max_contacts>
            <surface>
              <contact>
                <ode/>
              </contact>
              <bounce/>
              <friction>
                <torsional>
                  <ode/>
                </torsional>
                <ode/>
              </friction>
            </surface>
          </collision>
          <visual name='visual'>
            <pose frame=''>0 0 0 0 0 -1.5708</pose>
            <geometry>
              <mesh>
                <uri>model://pickup/meshes/pickup.dae</uri>
              </mesh>
            </geometry>
          </visual>
          <self_collide>0</self_collide>
          <kinematic>0</kinematic>
          <gravity>1</gravity>
        </link>
        <pose frame=''>-6.25239 -5.15928 0 0 -0 0</pose>
      </model>
      <model name='pine_tree'>
        <static>1</static>
        <link name='link'>
          <collision name='collision'>
            <geometry>
              <mesh>
                <uri>model://pine_tree/meshes/pine_tree.dae</uri>
              </mesh>
            </geometry>
            <max_contacts>10</max_contacts>
            <surface>
              <contact>
                <ode/>
              </contact>
              <bounce/>
              <friction>
                <torsional>
                  <ode/>
                </torsional>
                <ode/>
              </friction>
            </surface>
          </collision>
          <visual name='branch'>
            <geometry>
              <mesh>
                <uri>model://pine_tree/meshes/pine_tree.dae</uri>
                <submesh>
                  <name>Branch</name>
                </submesh>
              </mesh>
            </geometry>
            <material>
              <script>
                <uri>model://pine_tree/materials/scripts/</uri>
                <uri>model://pine_tree/materials/textures/</uri>
                <name>PineTree/Branch</name>
              </script>
            </material>
          </visual>
          <visual name='bark'>
            <geometry>
              <mesh>
                <uri>model://pine_tree/meshes/pine_tree.dae</uri>
                <submesh>
                  <name>Bark</name>
                </submesh>
              </mesh>
            </geometry>
            <material>
              <script>
                <uri>model://pine_tree/materials/scripts/</uri>
                <uri>model://pine_tree/materials/textures/</uri>
                <name>PineTree/Bark</name>
              </script>
            </material>
          </visual>
          <self_collide>0</self_collide>
          <kinematic>0</kinematic>
          <gravity>1</gravity>
        </link>
        <pose frame=''>0.236687 9.31571 0 0 -0 0</pose>
      </model>
      <model name='pine_tree_4'>
        <static>1</static>
        <link name='link'>
          <collision name='collision'>
            <geometry>
              <mesh>
                <uri>model://pine_tree/meshes/pine_tree.dae</uri>
              </mesh>
            </geometry>
            <max_contacts>10</max_contacts>
            <surface>
              <contact>
                <ode/>
              </contact>
              <bounce/>
              <friction>
                <torsional>
                  <ode/>
                </torsional>
                <ode/>
              </friction>
            </surface>
          </collision>
          <visual name='branch'>
            <geometry>
              <mesh>
                <uri>model://pine_tree/meshes/pine_tree.dae</uri>
                <submesh>
                  <name>Branch</name>
                </submesh>
              </mesh>
            </geometry>
            <material>
              <script>
                <uri>model://pine_tree/materials/scripts/</uri>
                <uri>model://pine_tree/materials/textures/</uri>
                <name>PineTree/Branch</name>
              </script>
            </material>
          </visual>
          <visual name='bark'>
            <geometry>
              <mesh>
                <uri>model://pine_tree/meshes/pine_tree.dae</uri>
                <submesh>
                  <name>Bark</name>
                </submesh>
              </mesh>
            </geometry>
            <material>
              <script>
                <uri>model://pine_tree/materials/scripts/</uri>
                <uri>model://pine_tree/materials/textures/</uri>
                <name>PineTree/Bark</name>
              </script>
            </material>
          </visual>
          <self_collide>0</self_collide>
          <kinematic>0</kinematic>
          <gravity>1</gravity>
        </link>
        <pose frame=''>7.74761 9.84071 0 0 -0 0</pose>
      </model>
      <model name='polaris_ranger_xp900'>
        <static>0</static>
        <link name='chassis'>
          <inertial>
            <mass>720</mass>
            <inertia>
              <ixx>140</ixx>
              <ixy>0</ixy>
              <iyy>550</iyy>
              <ixz>0</ixz>
              <iyz>0</iyz>
              <izz>550</izz>
            </inertia>
            <pose frame=''>0.1 0 0.4 0 -0 0</pose>
          </inertial>
          <visual name='visual'>
            <pose frame=''>0 0 0 0 0 -1.5708</pose>
            <geometry>
              <mesh>
                <uri>model://polaris_ranger_xp900/meshes/polaris.dae</uri>
                <submesh>
                  <name>Body</name>
                  <center>0</center>
                </submesh>
              </mesh>
            </geometry>
            <material>
              <script>
                <uri>model://polaris_ranger_xp900/materials/scripts</uri>
                <uri>model://polaris_ranger_xp900/materials/textures</uri>
                <name>PolarisXP900/Diffuse</name>
              </script>
            </material>
          </visual>
          <collision name='chassis_bottom'>
            <pose frame=''>0.2 0 0.335 0 -0 0</pose>
            <geometry>
              <box>
                <size>1.34 1.65746 0.06</size>
              </box>
            </geometry>
            <max_contacts>10</max_contacts>
            <surface>
              <contact>
                <ode/>
              </contact>
              <bounce/>
              <friction>
                <torsional>
                  <ode/>
                </torsional>
                <ode/>
              </friction>
            </surface>
          </collision>
          <collision name='cargo_bottom'>
            <pose frame=''>-1 0 0.921 0 -0 0</pose>
            <geometry>
              <box>
                <size>1.04609 1.6998 0.01</size>
              </box>
            </geometry>
            <max_contacts>10</max_contacts>
            <surface>
              <contact>
                <ode/>
              </contact>
              <bounce/>
              <friction>
                <torsional>
                  <ode/>
                </torsional>
                <ode/>
              </friction>
            </surface>
          </collision>
          <collision name='cargo_front'>
            <pose frame=''>-0.495 0 1.06 0 -0 0</pose>
            <geometry>
              <box>
                <size>0.05 1.69982 0.27</size>
              </box>
            </geometry>
            <max_contacts>10</max_contacts>
            <surface>
              <contact>
                <ode/>
              </contact>
              <bounce/>
              <friction>
                <torsional>
                  <ode/>
                </torsional>
                <ode/>
              </friction>
            </surface>
          </collision>
          <collision name='cargo_back'>
            <pose frame=''>-1.465 0 1.06 0 -0 0</pose>
            <geometry>
              <box>
                <size>0.05 1.69982 0.27</size>
              </box>
            </geometry>
            <max_contacts>10</max_contacts>
            <surface>
              <contact>
                <ode/>
              </contact>
              <bounce/>
              <friction>
                <torsional>
                  <ode/>
                </torsional>
                <ode/>
              </friction>
            </surface>
          </collision>
          <collision name='cargo_left'>
            <pose frame=''>-0.97 0.82491 1.06 0 -0 0</pose>
            <geometry>
              <box>
                <size>1.04609 0.05 0.27</size>
              </box>
            </geometry>
            <max_contacts>10</max_contacts>
            <surface>
              <contact>
                <ode/>
              </contact>
              <bounce/>
              <friction>
                <torsional>
                  <ode/>
                </torsional>
                <ode/>
              </friction>
            </surface>
          </collision>
          <collision name='cargo_right'>
            <pose frame=''>-0.97 -0.82491 1.06 0 -0 0</pose>
            <geometry>
              <box>
                <size>1.04609 0.05 0.27</size>
              </box>
            </geometry>
            <max_contacts>10</max_contacts>
            <surface>
              <contact>
                <ode/>
              </contact>
              <bounce/>
              <friction>
                <torsional>
                  <ode/>
                </torsional>
                <ode/>
              </friction>
            </surface>
          </collision>
          <collision name='seat'>
            <pose frame=''>0 0 0.62 0 -0 0</pose>
            <geometry>
              <box>
                <size>0.52167 1.37206 0.53369</size>
              </box>
            </geometry>
            <surface>
              <contact>
                <ode>
                  <min_depth>0.01</min_depth>
                </ode>
              </contact>
              <bounce/>
              <friction>
                <torsional>
                  <ode/>
                </torsional>
                <ode/>
              </friction>
            </surface>
            <max_contacts>10</max_contacts>
          </collision>
          <collision name='mud_seat'>
            <pose frame=''>0 0 0.86 0 -0 0</pose>
            <geometry>
              <box>
                <size>0.52167 1.3 0.1</size>
              </box>
            </geometry>
            <surface>
              <contact>
                <collide_without_contact>1</collide_without_contact>
                <ode/>
              </contact>
              <bounce/>
              <friction>
                <torsional>
                  <ode/>
                </torsional>
                <ode/>
              </friction>
            </surface>
            <max_contacts>10</max_contacts>
          </collision>
          <sensor name='seat_contact' type='contact'>
            <always_on>1</always_on>
            <update_rate>1000</update_rate>
            <contact>
              <collision>mud_seat</collision>
              <topic>__default_topic__</topic>
            </contact>
          </sensor>
          <collision name='seat_back'>
            <pose frame=''>-0.26 0 1.125 0 -0.2 0</pose>
            <geometry>
              <box>
                <size>0.06 1.37206 0.6</size>
              </box>
            </geometry>
            <max_contacts>10</max_contacts>
            <surface>
              <contact>
                <ode/>
              </contact>
              <bounce/>
              <friction>
                <torsional>
                  <ode/>
                </torsional>
                <ode/>
              </friction>
            </surface>
          </collision>
          <collision name='engine'>
            <pose frame=''>1.12 0 0.7 0 -0 0</pose>
            <geometry>
              <box>
                <size>0.58 1.3 0.8</size>
              </box>
            </geometry>
            <max_contacts>10</max_contacts>
            <surface>
              <contact>
                <ode/>
              </contact>
              <bounce/>
              <friction>
                <torsional>
                  <ode/>
                </torsional>
                <ode/>
              </friction>
            </surface>
          </collision>
          <collision name='rollcage_top_left'>
            <pose frame=''>-0.02 0.76 1.936 3.14159 1.54159 3.14159</pose>
            <geometry>
              <cylinder>
                <radius>0.03</radius>
                <length>0.68</length>
              </cylinder>
            </geometry>
            <max_contacts>10</max_contacts>
            <surface>
              <contact>
                <ode/>
              </contact>
              <bounce/>
              <friction>
                <torsional>
                  <ode/>
                </torsional>
                <ode/>
              </friction>
            </surface>
          </collision>
          <collision name='rollcage_top_right'>
            <pose frame=''>-0.02 -0.76 1.936 3.14159 1.54159 3.14159</pose>
            <geometry>
              <cylinder>
                <radius>0.03</radius>
                <length>0.68</length>
              </cylinder>
            </geometry>
            <max_contacts>10</max_contacts>
            <surface>
              <contact>
                <ode/>
              </contact>
              <bounce/>
              <friction>
                <torsional>
                  <ode/>
                </torsional>
                <ode/>
              </friction>
            </surface>
          </collision>
          <collision name='rollcage_top_front'>
            <pose frame=''>0.315 0 1.93 0 -1 0</pose>
            <geometry>
              <box>
                <size>0.01299 1.54 0.10226</size>
              </box>
            </geometry>
            <max_contacts>10</max_contacts>
            <surface>
              <contact>
                <ode/>
              </contact>
              <bounce/>
              <friction>
                <torsional>
                  <ode/>
                </torsional>
                <ode/>
              </friction>
            </surface>
          </collision>
          <collision name='rollcage_top_back'>
            <pose frame=''>-0.41 0 1.88 0 -0 0</pose>
            <geometry>
              <box>
                <size>0.01299 1.54 0.10226</size>
              </box>
            </geometry>
            <max_contacts>10</max_contacts>
            <surface>
              <contact>
                <ode/>
              </contact>
              <bounce/>
              <friction>
                <torsional>
                  <ode/>
                </torsional>
                <ode/>
              </friction>
            </surface>
          </collision>
          <collision name='rollcage_front_left'>
            <pose frame=''>0.602 0.755 1.45 0 -0.54 0</pose>
            <geometry>
              <cylinder>
                <radius>0.03</radius>
                <length>1.15</length>
              </cylinder>
            </geometry>
            <max_contacts>10</max_contacts>
            <surface>
              <contact>
                <ode/>
              </contact>
              <bounce/>
              <friction>
                <torsional>
                  <ode/>
                </torsional>
                <ode/>
              </friction>
            </surface>
          </collision>
          <collision name='rollcage_front_right'>
            <pose frame=''>0.602 -0.755 1.45 0 -0.54 0</pose>
            <geometry>
              <cylinder>
                <radius>0.03</radius>
                <length>1.15</length>
              </cylinder>
            </geometry>
            <max_contacts>10</max_contacts>
            <surface>
              <contact>
                <ode/>
              </contact>
              <bounce/>
              <friction>
                <torsional>
                  <ode/>
                </torsional>
                <ode/>
              </friction>
            </surface>
          </collision>
          <collision name='rollcage_back_left'>
            <pose frame=''>-0.4 0.755 1.45 0 -0 0</pose>
            <geometry>
              <cylinder>
                <radius>0.03</radius>
                <length>1</length>
              </cylinder>
            </geometry>
            <max_contacts>10</max_contacts>
            <surface>
              <contact>
                <ode/>
              </contact>
              <bounce/>
              <friction>
                <torsional>
                  <ode/>
                </torsional>
                <ode/>
              </friction>
            </surface>
          </collision>
          <collision name='rollcage_back_right'>
            <pose frame=''>-0.4 -0.755 1.45 0 -0 0</pose>
            <geometry>
              <cylinder>
                <radius>0.03</radius>
                <length>1</length>
              </cylinder>
            </geometry>
            <max_contacts>10</max_contacts>
            <surface>
              <contact>
                <ode/>
              </contact>
              <bounce/>
              <friction>
                <torsional>
                  <ode/>
                </torsional>
                <ode/>
              </friction>
            </surface>
          </collision>
          <collision name='rollcage_X_1'>
            <pose frame=''>-0.411 0.04 1.445 0.397 -0 0</pose>
            <geometry>
              <box>
                <size>0.01392 1.55724 0.078</size>
              </box>
            </geometry>
            <max_contacts>10</max_contacts>
            <surface>
              <contact>
                <ode/>
              </contact>
              <bounce/>
              <friction>
                <torsional>
                  <ode/>
                </torsional>
                <ode/>
              </friction>
            </surface>
          </collision>
          <collision name='rollcage_X_2'>
            <pose frame=''>-0.4 -0.04 1.445 -0.397 0 0</pose>
            <geometry>
              <box>
                <size>0.01392 1.55724 0.078</size>
              </box>
            </geometry>
            <max_contacts>10</max_contacts>
            <surface>
              <contact>
                <ode/>
              </contact>
              <bounce/>
              <friction>
                <torsional>
                  <ode/>
                </torsional>
                <ode/>
              </friction>
            </surface>
          </collision>
          <collision name='central_hump1_collision'>
            <pose frame=''>0.55 -0.1 0.4 0 -0 0</pose>
            <geometry>
              <box>
                <size>0.6 0.15 0.1</size>
              </box>
            </geometry>
            <max_contacts>10</max_contacts>
            <surface>
              <contact>
                <ode/>
              </contact>
              <bounce/>
              <friction>
                <torsional>
                  <ode/>
                </torsional>
                <ode/>
              </friction>
            </surface>
          </collision>
          <collision name='central_hump2_collision'>
            <pose frame=''>0.7 -0.05 0.45 0 -0.5 0</pose>
            <geometry>
              <box>
                <size>0.2 0.05 0.1</size>
              </box>
            </geometry>
            <max_contacts>10</max_contacts>
            <surface>
              <contact>
                <ode/>
              </contact>
              <bounce/>
              <friction>
                <torsional>
                  <ode/>
                </torsional>
                <ode/>
              </friction>
            </surface>
          </collision>
          <collision name='central_hump3_collision'>
            <pose frame=''>0.798 -0.125 0.478 0 -0.8 0</pose>
            <geometry>
              <box>
                <size>0.129 0.1 0.05</size>
              </box>
            </geometry>
            <max_contacts>10</max_contacts>
            <surface>
              <contact>
                <ode/>
              </contact>
              <bounce/>
              <friction>
                <torsional>
                  <ode/>
                </torsional>
                <ode/>
              </friction>
            </surface>
          </collision>
          <collision name='central_hump4_collision'>
            <pose frame=''>0.8135 -0.05 0.45 0 -0 0</pose>
            <geometry>
              <box>
                <size>0.1 0.05 0.1835</size>
              </box>
            </geometry>
            <max_contacts>10</max_contacts>
            <surface>
              <contact>
                <ode/>
              </contact>
              <bounce/>
              <friction>
                <torsional>
                  <ode/>
                </torsional>
                <ode/>
              </friction>
            </surface>
          </collision>
          <collision name='central_hump5_collision'>
            <pose frame=''>0.84 -0.125 0.45 0 -0 0</pose>
            <geometry>
              <box>
                <size>0.03 0.1 0.1835</size>
              </box>
            </geometry>
            <max_contacts>10</max_contacts>
            <surface>
              <contact>
                <ode/>
              </contact>
              <bounce/>
              <friction>
                <torsional>
                  <ode/>
                </torsional>
                <ode/>
              </friction>
            </surface>
          </collision>
          <collision name='central_hump6_collision'>
            <pose frame=''>0.82 -0.125 0.475 0 -0 0</pose>
            <geometry>
              <box>
                <size>0.03 0.1 0.05</size>
              </box>
            </geometry>
            <max_contacts>10</max_contacts>
            <surface>
              <contact>
                <ode/>
              </contact>
              <bounce/>
              <friction>
                <torsional>
                  <ode/>
                </torsional>
                <ode/>
              </friction>
            </surface>
          </collision>
          <visual name='cargo_visual'>
            <pose frame=''>-1 0 1.0323 0 0 -1.5707</pose>
            <geometry>
              <mesh>
                <uri>model://polaris_ranger_xp900/meshes/polaris.dae</uri>
                <submesh>
                  <name>Bed</name>
                  <center>1</center>
                </submesh>
              </mesh>
            </geometry>
            <material>
              <script>
                <uri>model://polaris_ranger_xp900/materials/scripts</uri>
                <uri>model://polaris_ranger_xp900/materials/textures</uri>
                <name>PolarisXP900/Diffuse</name>
              </script>
            </material>
          </visual>
          <visual name='tailgate_visual'>
            <pose frame=''>-1.492 0 1.03 0 0 -1.5707</pose>
            <geometry>
              <mesh>
                <uri>model://polaris_ranger_xp900/meshes/polaris.dae</uri>
                <submesh>
                  <name>Tail_Gate</name>
                  <center>1</center>
                </submesh>
              </mesh>
            </geometry>
            <material>
              <script>
                <uri>model://polaris_ranger_xp900/materials/scripts</uri>
                <uri>model://polaris_ranger_xp900/materials/textures</uri>
                <name>PolarisXP900/Diffuse</name>
              </script>
            </material>
          </visual>
          <visual name='front_left_brake_visual'>
            <pose frame=''>1.12 -0.57488 0.35516 3.1415 -0 1.5707</pose>
            <geometry>
              <mesh>
                <uri>model://polaris_ranger_xp900/meshes/polaris.dae</uri>
                <submesh>
                  <name>Brake_Front_Left</name>
                  <center>1</center>
                </submesh>
              </mesh>
            </geometry>
            <material>
              <script>
                <uri>model://polaris_ranger_xp900/materials/scripts</uri>
                <uri>model://polaris_ranger_xp900/materials/textures</uri>
                <name>PolarisXP900/Diffuse</name>
              </script>
            </material>
          </visual>
          <visual name='front_right_brake_visual'>
            <pose frame=''>1.12 0.57488 0.35516 3.1415 -0 1.5707</pose>
            <geometry>
              <mesh>
                <uri>model://polaris_ranger_xp900/meshes/polaris.dae</uri>
                <submesh>
                  <name>Brake_Front_Right</name>
                  <center>1</center>
                </submesh>
              </mesh>
            </geometry>
            <material>
              <script>
                <uri>model://polaris_ranger_xp900/materials/scripts</uri>
                <uri>model://polaris_ranger_xp900/materials/textures</uri>
                <name>PolarisXP900/Diffuse</name>
              </script>
            </material>
          </visual>
          <visual name='central_hump1'>
            <pose frame=''>0.55 -0.1 0.4 0 -0 0</pose>
            <geometry>
              <box>
                <size>0.6 0.15 0.1</size>
              </box>
            </geometry>
            <material>
              <script>
                <uri>file://media/materials/scripts/gazebo.material</uri>
                <name>Gazebo/DarkGrey</name>
              </script>
            </material>
          </visual>
          <visual name='central_hump2'>
            <pose frame=''>0.7 -0.05 0.45 0 -0.5 0</pose>
            <geometry>
              <box>
                <size>0.2 0.05 0.1</size>
              </box>
            </geometry>
            <material>
              <script>
                <uri>file://media/materials/scripts/gazebo.material</uri>
                <name>Gazebo/DarkGrey</name>
              </script>
            </material>
          </visual>
          <visual name='central_hump3'>
            <pose frame=''>0.798 -0.125 0.478 0 -0.8 0</pose>
            <geometry>
              <box>
                <size>0.129 0.1 0.05</size>
              </box>
            </geometry>
            <material>
              <script>
                <uri>file://media/materials/scripts/gazebo.material</uri>
                <name>Gazebo/DarkGrey</name>
              </script>
            </material>
          </visual>
          <visual name='central_hump4'>
            <pose frame=''>0.8135 -0.05 0.45 0 -0 0</pose>
            <geometry>
              <box>
                <size>0.1 0.05 0.1835</size>
              </box>
            </geometry>
            <material>
              <script>
                <uri>file://media/materials/scripts/gazebo.material</uri>
                <name>Gazebo/DarkGrey</name>
              </script>
            </material>
          </visual>
          <visual name='central_hump5'>
            <pose frame=''>0.84 -0.125 0.45 0 -0 0</pose>
            <geometry>
              <box>
                <size>0.03 0.1 0.1835</size>
              </box>
            </geometry>
            <material>
              <script>
                <uri>file://media/materials/scripts/gazebo.material</uri>
                <name>Gazebo/DarkGrey</name>
              </script>
            </material>
          </visual>
          <visual name='central_hump6'>
            <pose frame=''>0.82 -0.125 0.475 0 -0 0</pose>
            <geometry>
              <box>
                <size>0.03 0.1 0.05</size>
              </box>
            </geometry>
            <material>
              <script>
                <uri>file://media/materials/scripts/gazebo.material</uri>
                <name>Gazebo/DarkGrey</name>
              </script>
            </material>
          </visual>
          <self_collide>0</self_collide>
          <kinematic>0</kinematic>
          <gravity>1</gravity>
        </link>
        <link name='front_left_wheel'>
          <pose frame=''>1.20223 0.71562 0.34697 -1.52 0 0</pose>
          <inertial>
            <mass>12</mass>
            <inertia>
              <ixx>0.5</ixx>
              <ixy>0</ixy>
              <iyy>0.5</iyy>
              <ixz>0</ixz>
              <iyz>0</iyz>
              <izz>1</izz>
            </inertia>
          </inertial>
          <collision name='collision'>
            <geometry>
              <cylinder>
                <radius>0.3175</radius>
                <length>0.2794</length>
              </cylinder>
            </geometry>
            <max_contacts>1</max_contacts>
            <surface>
              <friction>
                <ode>
                  <mu>1</mu>
                  <mu2>1</mu2>
                  <fdir1>0 0 1</fdir1>
                  <slip1>0</slip1>
                  <slip2>0</slip2>
                </ode>
                <torsional>
                  <ode/>
                </torsional>
              </friction>
              <contact>
                <ode>
                  <min_depth>0.005</min_depth>
                  <kp>1e+08</kp>
                </ode>
              </contact>
              <bounce/>
            </surface>
          </collision>
          <visual name='tire_visual'>
            <pose frame=''>0 0 0 -3e-06 1.57079 3.14159</pose>
            <geometry>
              <mesh>
                <uri>model://polaris_ranger_xp900/meshes/polaris.dae</uri>
                <scale>1.0037 0.8862 0.8862</scale>
                <submesh>
                  <name>Wheel_Front_Left</name>
                  <center>1</center>
                </submesh>
              </mesh>
            </geometry>
            <material>
              <script>
                <uri>model://polaris_ranger_xp900/materials/scripts</uri>
                <uri>model://polaris_ranger_xp900/materials/textures</uri>
                <name>PolarisXP900/Diffuse</name>
              </script>
            </material>
          </visual>
          <self_collide>0</self_collide>
          <kinematic>0</kinematic>
          <gravity>1</gravity>
        </link>
        <link name='front_right_wheel'>
          <pose frame=''>1.20223 -0.71562 0.34697 1.52 -0 0</pose>
          <inertial>
            <mass>12</mass>
            <inertia>
              <ixx>0.5</ixx>
              <ixy>0</ixy>
              <iyy>0.5</iyy>
              <ixz>0</ixz>
              <iyz>0</iyz>
              <izz>1</izz>
            </inertia>
          </inertial>
          <collision name='collision'>
            <geometry>
              <cylinder>
                <radius>0.3175</radius>
                <length>0.2794</length>
              </cylinder>
            </geometry>
            <max_contacts>1</max_contacts>
            <surface>
              <friction>
                <ode>
                  <mu>1</mu>
                  <mu2>1</mu2>
                  <fdir1>0 0 1</fdir1>
                  <slip1>0</slip1>
                  <slip2>0</slip2>
                </ode>
                <torsional>
                  <ode/>
                </torsional>
              </friction>
              <contact>
                <ode>
                  <min_depth>0.005</min_depth>
                  <kp>1e+08</kp>
                </ode>
              </contact>
              <bounce/>
            </surface>
          </collision>
          <visual name='visual'>
            <pose frame=''>0 0 0 3.14159 -1.57079 3.14159</pose>
            <geometry>
              <mesh>
                <uri>model://polaris_ranger_xp900/meshes/polaris.dae</uri>
                <scale>1.0037 0.8862 0.8862</scale>
                <submesh>
                  <name>Wheel_Front_Right</name>
                  <center>1</center>
                </submesh>
              </mesh>
            </geometry>
            <material>
              <script>
                <uri>model://polaris_ranger_xp900/materials/scripts</uri>
                <uri>model://polaris_ranger_xp900/materials/textures</uri>
                <name>PolarisXP900/Diffuse</name>
              </script>
            </material>
          </visual>
          <self_collide>0</self_collide>
          <kinematic>0</kinematic>
          <gravity>1</gravity>
        </link>
        <link name='rear_left_wheel'>
          <pose frame=''>-0.99377 0.71562 0.34697 -1.52 0 0</pose>
          <inertial>
            <mass>12</mass>
            <inertia>
              <ixx>0.5</ixx>
              <ixy>0</ixy>
              <iyy>0.5</iyy>
              <ixz>0</ixz>
              <iyz>0</iyz>
              <izz>1</izz>
            </inertia>
          </inertial>
          <collision name='collision'>
            <geometry>
              <cylinder>
                <radius>0.3175</radius>
                <length>0.2794</length>
              </cylinder>
            </geometry>
            <max_contacts>1</max_contacts>
            <surface>
              <friction>
                <ode>
                  <mu>1</mu>
                  <mu2>1</mu2>
                  <fdir1>0 0 1</fdir1>
                  <slip1>0</slip1>
                  <slip2>0</slip2>
                </ode>
                <torsional>
                  <ode/>
                </torsional>
              </friction>
              <contact>
                <ode>
                  <min_depth>0.005</min_depth>
                  <kp>1e+08</kp>
                </ode>
              </contact>
              <bounce/>
            </surface>
          </collision>
          <visual name='visual'>
            <pose frame=''>0 0 0 3.14159 -1.57079 3.14159</pose>
            <geometry>
              <mesh>
                <uri>model://polaris_ranger_xp900/meshes/polaris.dae</uri>
                <scale>1.0037 0.8862 0.8862</scale>
                <submesh>
                  <name>Wheels_Rear_Left</name>
                  <center>1</center>
                </submesh>
              </mesh>
            </geometry>
            <material>
              <script>
                <uri>model://polaris_ranger_xp900/materials/scripts</uri>
                <uri>model://polaris_ranger_xp900/materials/textures</uri>
                <name>PolarisXP900/Diffuse</name>
              </script>
            </material>
          </visual>
          <self_collide>0</self_collide>
          <kinematic>0</kinematic>
          <gravity>1</gravity>
        </link>
        <link name='rear_right_wheel'>
          <pose frame=''>-0.99377 -0.71562 0.34697 1.52 -0 0</pose>
          <inertial>
            <mass>12</mass>
            <inertia>
              <ixx>0.5</ixx>
              <ixy>0</ixy>
              <iyy>0.5</iyy>
              <ixz>0</ixz>
              <iyz>0</iyz>
              <izz>1</izz>
            </inertia>
          </inertial>
          <collision name='collision'>
            <geometry>
              <cylinder>
                <radius>0.3175</radius>
                <length>0.2794</length>
              </cylinder>
            </geometry>
            <max_contacts>1</max_contacts>
            <surface>
              <friction>
                <ode>
                  <mu>1</mu>
                  <mu2>1</mu2>
                  <fdir1>0 0 1</fdir1>
                  <slip1>0</slip1>
                  <slip2>0</slip2>
                </ode>
                <torsional>
                  <ode/>
                </torsional>
              </friction>
              <contact>
                <ode>
                  <min_depth>0.005</min_depth>
                  <kp>1e+08</kp>
                </ode>
              </contact>
              <bounce/>
            </surface>
          </collision>
          <visual name='visual'>
            <pose frame=''>0 0 0 3.14159 -1.57079 3.14159</pose>
            <geometry>
              <mesh>
                <uri>model://polaris_ranger_xp900/meshes/polaris.dae</uri>
                <scale>1.0037 0.8862 0.8862</scale>
                <submesh>
                  <name>Wheels_Rear_Right</name>
                  <center>1</center>
                </submesh>
              </mesh>
            </geometry>
            <material>
              <script>
                <uri>model://polaris_ranger_xp900/materials/scripts</uri>
                <uri>model://polaris_ranger_xp900/materials/textures</uri>
                <name>PolarisXP900/Diffuse</name>
              </script>
            </material>
          </visual>
          <self_collide>0</self_collide>
          <kinematic>0</kinematic>
          <gravity>1</gravity>
        </link>
        <link name='gas_pedal'>
          <pose frame=''>0.63 0.1 0.58 0 -0 0</pose>
          <gravity>0</gravity>
          <inertial>
            <mass>0.1</mass>
            <pose frame=''>0 0 0 0 -0 0</pose>
            <inertia>
              <ixx>0.01</ixx>
              <ixy>0</ixy>
              <ixz>0</ixz>
              <iyy>0.01</iyy>
              <iyz>0</iyz>
              <izz>0.01</izz>
            </inertia>
          </inertial>
          <collision name='gas_pedal_collision'>
            <pose frame=''>-0.0385 0 -0.086 3.14159 1.12559 3.14159</pose>
            <geometry>
              <box>
                <size>0.1069 0.077 0.01</size>
              </box>
            </geometry>
            <max_contacts>10</max_contacts>
            <surface>
              <contact>
                <ode/>
              </contact>
              <bounce/>
              <friction>
                <torsional>
                  <ode/>
                </torsional>
                <ode/>
              </friction>
            </surface>
          </collision>
          <visual name='visual'>
            <pose frame=''>0 0 0 0 0 -1.5707</pose>
            <geometry>
              <mesh>
                <uri>model://polaris_ranger_xp900/meshes/polaris.dae</uri>
                <submesh>
                  <name>Gas_Pedal</name>
                  <center>1</center>
                </submesh>
              </mesh>
            </geometry>
            <material>
              <script>
                <uri>model://polaris_ranger_xp900/materials/scripts</uri>
                <uri>model://polaris_ranger_xp900/materials/textures</uri>
                <name>PolarisXP900/Diffuse</name>
              </script>
            </material>
          </visual>
          <self_collide>0</self_collide>
          <kinematic>0</kinematic>
        </link>
        <link name='brake_pedal'>
          <gravity>0</gravity>
          <pose frame=''>0.64 0.27 0.58 0 -0 0</pose>
          <inertial>
            <mass>0.1</mass>
            <pose frame=''>0 0 0 0 -0 0</pose>
            <inertia>
              <ixx>0.01</ixx>
              <ixy>0</ixy>
              <ixz>0</ixz>
              <iyy>0.01</iyy>
              <iyz>0</iyz>
              <izz>0.01</izz>
            </inertia>
          </inertial>
          <collision name='brake_pedal_collision'>
            <pose frame=''>-0.04 0 -0.086 3.14159 1.14259 3.14159</pose>
            <geometry>
              <box>
                <size>0.063 0.08 0.01</size>
              </box>
            </geometry>
            <max_contacts>10</max_contacts>
            <surface>
              <contact>
                <ode/>
              </contact>
              <bounce/>
              <friction>
                <torsional>
                  <ode/>
                </torsional>
                <ode/>
              </friction>
            </surface>
          </collision>
          <visual name='visual'>
            <pose frame=''>0 0 0 0 0 -1.5707</pose>
            <geometry>
              <mesh>
                <uri>model://polaris_ranger_xp900/meshes/polaris.dae</uri>
                <submesh>
                  <name>Brake_Pedal</name>
                  <center>1</center>
                </submesh>
              </mesh>
            </geometry>
            <material>
              <script>
                <uri>model://polaris_ranger_xp900/materials/scripts</uri>
                <uri>model://polaris_ranger_xp900/materials/textures</uri>
                <name>PolarisXP900/Diffuse</name>
              </script>
            </material>
          </visual>
          <self_collide>0</self_collide>
          <kinematic>0</kinematic>
        </link>
        <link name='front_right_wheel_steering_block'>
          <pose frame=''>1.20223 -0.5 0.35515 1.5708 -0 0</pose>
          <inertial>
            <mass>1</mass>
            <inertia>
              <ixx>1</ixx>
              <ixy>0</ixy>
              <iyy>1</iyy>
              <ixz>0</ixz>
              <iyz>0</iyz>
              <izz>1</izz>
            </inertia>
          </inertial>
          <collision name='collision'>
            <geometry>
              <cylinder>
                <radius>0.05</radius>
                <length>0.01</length>
              </cylinder>
            </geometry>
            <max_contacts>10</max_contacts>
            <surface>
              <contact>
                <ode/>
              </contact>
              <bounce/>
              <friction>
                <torsional>
                  <ode/>
                </torsional>
                <ode/>
              </friction>
            </surface>
          </collision>
          <self_collide>0</self_collide>
          <kinematic>0</kinematic>
          <gravity>1</gravity>
        </link>
        <link name='front_left_wheel_steering_block'>
          <pose frame=''>1.20223 0.5 0.35515 1.5708 -0 0</pose>
          <inertial>
            <mass>1</mass>
            <inertia>
              <ixx>1</ixx>
              <ixy>0</ixy>
              <iyy>1</iyy>
              <ixz>0</ixz>
              <iyz>0</iyz>
              <izz>1</izz>
            </inertia>
          </inertial>
          <collision name='collision'>
            <geometry>
              <cylinder>
                <radius>0.05</radius>
                <length>0.01</length>
              </cylinder>
            </geometry>
            <max_contacts>10</max_contacts>
            <surface>
              <contact>
                <ode/>
              </contact>
              <bounce/>
              <friction>
                <torsional>
                  <ode/>
                </torsional>
                <ode/>
              </friction>
            </surface>
          </collision>
          <self_collide>0</self_collide>
          <kinematic>0</kinematic>
          <gravity>1</gravity>
        </link>
        <link name='steering_wheel'>
          <pose frame=''>0.42 0.46 1.2 0 -0.87 0</pose>
          <inertial>
            <mass>1</mass>
            <pose frame=''>-0.002 0 0 0 -0 0</pose>
            <inertia>
              <ixx>0.012</ixx>
              <ixy>0</ixy>
              <ixz>0</ixz>
              <iyy>0.012</iyy>
              <iyz>0</iyz>
              <izz>0.024</izz>
            </inertia>
          </inertial>
          <collision name='collision'>
            <pose frame=''>-0.03 0 -0.120825 -0.6108 -0 -1.5708</pose>
            <geometry>
              <mesh>
                <uri>model://polaris_ranger_xp900/meshes/polaris.dae</uri>
                <submesh>
                  <name>Steering_Wheel</name>
                  <center>1</center>
                </submesh>
              </mesh>
            </geometry>
            <surface>
              <contact>
                <ode>
                  <min_depth>0.003</min_depth>
                </ode>
              </contact>
              <bounce/>
              <friction>
                <torsional>
                  <ode/>
                </torsional>
                <ode/>
              </friction>
            </surface>
            <max_contacts>10</max_contacts>
          </collision>
          <visual name='visual'>
            <pose frame=''>-0.03 0 -0.120825 -0.6108 -0 -1.5708</pose>
            <geometry>
              <mesh>
                <uri>model://polaris_ranger_xp900/meshes/polaris.dae</uri>
                <submesh>
                  <name>Steering_Wheel</name>
                  <center>1</center>
                </submesh>
              </mesh>
            </geometry>
            <material>
              <script>
                <uri>model://polaris_ranger_xp900/materials/scripts</uri>
                <uri>model://polaris_ranger_xp900/materials/textures</uri>
                <name>PolarisXP900/Diffuse</name>
              </script>
            </material>
          </visual>
          <self_collide>0</self_collide>
          <kinematic>0</kinematic>
          <gravity>1</gravity>
        </link>
        <link name='hand_brake'>
          <pose frame=''>0.53 0.205 1.05 0 -0 0</pose>
          <inertial>
            <mass>0.5</mass>
            <inertia>
              <ixx>0.1</ixx>
              <ixy>0</ixy>
              <ixz>0</ixz>
              <iyy>0.1</iyy>
              <iyz>0</iyz>
              <izz>0.05</izz>
            </inertia>
          </inertial>
          <collision name='hand_brake_collision'>
            <pose frame=''>0 0 0.05 -0.2 -0 -1.5708</pose>
            <geometry>
              <mesh>
                <uri>model://polaris_ranger_xp900/meshes/polaris.dae</uri>
                <submesh>
                  <name>Shifter</name>
                  <center>1</center>
                </submesh>
              </mesh>
            </geometry>
            <max_contacts>10</max_contacts>
            <surface>
              <contact>
                <ode/>
              </contact>
              <bounce/>
              <friction>
                <torsional>
                  <ode/>
                </torsional>
                <ode/>
              </friction>
            </surface>
          </collision>
          <visual name='hand_brake_visual'>
            <pose frame=''>0 0 0.05 -0.2 -0 -1.5708</pose>
            <geometry>
              <mesh>
                <uri>model://polaris_ranger_xp900/meshes/polaris.dae</uri>
                <submesh>
                  <name>Shifter</name>
                  <center>1</center>
                </submesh>
              </mesh>
            </geometry>
            <material>
              <script>
                <uri>model://polaris_ranger_xp900/materials/scripts</uri>
                <uri>model://polaris_ranger_xp900/materials/textures</uri>
                <name>PolarisXP900/Diffuse</name>
              </script>
            </material>
          </visual>
          <self_collide>0</self_collide>
          <kinematic>0</kinematic>
          <gravity>1</gravity>
        </link>
        <link name='FNR_switch'>
          <pose frame=''>0.54 0.1 1.15 0 0.25 0</pose>
          <inertial>
            <mass>0.1</mass>
            <inertia>
              <ixx>0.1</ixx>
              <ixy>0</ixy>
              <ixz>0</ixz>
              <iyy>6e-05</iyy>
              <iyz>0</iyz>
              <izz>0.1</izz>
            </inertia>
          </inertial>
          <collision name='FNR_switch'>
            <geometry>
              <box>
                <size>0.02 0.04 0.08</size>
              </box>
            </geometry>
            <max_contacts>10</max_contacts>
            <surface>
              <contact>
                <ode/>
              </contact>
              <bounce/>
              <friction>
                <torsional>
                  <ode/>
                </torsional>
                <ode/>
              </friction>
            </surface>
          </collision>
          <visual name='FNR_switch_F'>
            <transparency>0</transparency>
            <geometry>
              <box>
                <size>0.02 0.04 0.08</size>
              </box>
            </geometry>
            <material>
              <script>
                <uri>model://polaris_ranger_ev/materials/scripts</uri>
                <uri>model://polaris_ranger_ev/materials/textures</uri>
                <name>FNR_switch_F</name>
              </script>
            </material>
          </visual>
          <visual name='FNR_switch_R'>
            <transparency>1</transparency>
            <geometry>
              <box>
                <size>0.0199 0.0399 0.0799</size>
              </box>
            </geometry>
            <material>
              <script>
                <uri>model://polaris_ranger_ev/materials/scripts</uri>
                <uri>model://polaris_ranger_ev/materials/textures</uri>
                <name>FNR_switch_R</name>
              </script>
            </material>
          </visual>
          <self_collide>0</self_collide>
          <kinematic>0</kinematic>
          <gravity>1</gravity>
        </link>
        <joint name='front_left_steering_joint' type='revolute'>
          <child>front_left_wheel_steering_block</child>
          <parent>chassis</parent>
          <axis>
            <xyz>0 0 1</xyz>
            <limit>
              <lower>-0.7727</lower>
              <upper>0.7727</upper>
            </limit>
            <dynamics>
              <damping>50</damping>
              <spring_reference>0</spring_reference>
              <spring_stiffness>0</spring_stiffness>
            </dynamics>
            <use_parent_model_frame>1</use_parent_model_frame>
          </axis>
          <physics>
            <ode>
              <cfm_damping>1</cfm_damping>
              <limit>
                <cfm>0</cfm>
                <erp>0.9</erp>
              </limit>
            </ode>
          </physics>
        </joint>
        <joint name='front_left_wheel_joint' type='revolute'>
          <child>front_left_wheel</child>
          <parent>front_left_wheel_steering_block</parent>
          <axis>
            <xyz>0 1 0.05</xyz>
            <use_parent_model_frame>1</use_parent_model_frame>
            <limit>
              <lower>-1e+16</lower>
              <upper>1e+16</upper>
            </limit>
            <dynamics>
              <spring_reference>0</spring_reference>
              <spring_stiffness>0</spring_stiffness>
            </dynamics>
          </axis>
        </joint>
        <joint name='front_right_steering_joint' type='revolute'>
          <child>front_right_wheel_steering_block</child>
          <parent>chassis</parent>
          <axis>
            <xyz>0 0 1</xyz>
            <limit>
              <lower>-0.7727</lower>
              <upper>0.7727</upper>
            </limit>
            <dynamics>
              <damping>50</damping>
              <spring_reference>0</spring_reference>
              <spring_stiffness>0</spring_stiffness>
            </dynamics>
            <use_parent_model_frame>1</use_parent_model_frame>
          </axis>
          <physics>
            <ode>
              <cfm_damping>1</cfm_damping>
              <limit>
                <cfm>0</cfm>
                <erp>0.9</erp>
              </limit>
            </ode>
          </physics>
        </joint>
        <joint name='front_right_wheel_joint' type='revolute'>
          <child>front_right_wheel</child>
          <parent>front_right_wheel_steering_block</parent>
          <axis>
            <xyz>0 1 -0.05</xyz>
            <use_parent_model_frame>1</use_parent_model_frame>
            <limit>
              <lower>-1e+16</lower>
              <upper>1e+16</upper>
            </limit>
            <dynamics>
              <spring_reference>0</spring_reference>
              <spring_stiffness>0</spring_stiffness>
            </dynamics>
          </axis>
        </joint>
        <joint name='rear_left_wheel_joint' type='revolute'>
          <child>rear_left_wheel</child>
          <parent>chassis</parent>
          <axis>
            <xyz>0 1 0.05</xyz>
            <use_parent_model_frame>1</use_parent_model_frame>
            <limit>
              <lower>-1e+16</lower>
              <upper>1e+16</upper>
            </limit>
            <dynamics>
              <spring_reference>0</spring_reference>
              <spring_stiffness>0</spring_stiffness>
            </dynamics>
          </axis>
        </joint>
        <joint name='rear_right_wheel_joint' type='revolute'>
          <pose frame=''>0 0 -0.1 0 -0 0</pose>
          <child>rear_right_wheel</child>
          <parent>chassis</parent>
          <axis>
            <xyz>0 1 -0.05</xyz>
            <use_parent_model_frame>1</use_parent_model_frame>
            <limit>
              <lower>-1e+16</lower>
              <upper>1e+16</upper>
            </limit>
            <dynamics>
              <spring_reference>0</spring_reference>
              <spring_stiffness>0</spring_stiffness>
            </dynamics>
          </axis>
        </joint>
        <joint name='rear_differential_joint' type='revolute'>
          <child>rear_right_wheel</child>
          <parent>rear_left_wheel</parent>
          <axis>
            <xyz>0 1 0</xyz>
            <dynamics>
              <damping>70</damping>
              <spring_reference>0</spring_reference>
              <spring_stiffness>0</spring_stiffness>
            </dynamics>
            <use_parent_model_frame>1</use_parent_model_frame>
            <limit>
              <lower>-1e+16</lower>
              <upper>1e+16</upper>
            </limit>
          </axis>
          <physics>
            <ode>
              <erp>0</erp>
              <cfm>1000</cfm>
              <cfm_damping>1</cfm_damping>
              <limit>
                <cfm>0</cfm>
                <erp>0.2</erp>
              </limit>
            </ode>
          </physics>
        </joint>
        <joint name='gas_joint' type='prismatic'>
          <parent>chassis</parent>
          <child>gas_pedal</child>
          <axis>
            <xyz>1 0 -1</xyz>
            <limit>
              <lower>0</lower>
              <upper>0.08</upper>
            </limit>
            <dynamics>
              <damping>3</damping>
              <spring_reference>0</spring_reference>
              <spring_stiffness>0</spring_stiffness>
            </dynamics>
            <use_parent_model_frame>1</use_parent_model_frame>
          </axis>
          <physics>
            <ode>
              <cfm_damping>1</cfm_damping>
              <limit>
                <cfm>0</cfm>
                <erp>0.2</erp>
              </limit>
            </ode>
          </physics>
        </joint>
        <joint name='brake_joint' type='prismatic'>
          <parent>chassis</parent>
          <child>brake_pedal</child>
          <axis>
            <xyz>1 0 -0.6</xyz>
            <limit>
              <lower>0</lower>
              <upper>0.08</upper>
            </limit>
            <dynamics>
              <damping>3</damping>
              <spring_reference>0</spring_reference>
              <spring_stiffness>0</spring_stiffness>
            </dynamics>
            <use_parent_model_frame>1</use_parent_model_frame>
          </axis>
          <physics>
            <ode>
              <cfm_damping>1</cfm_damping>
              <limit>
                <cfm>0</cfm>
                <erp>0.2</erp>
              </limit>
            </ode>
          </physics>
        </joint>
        <joint name='steering_joint' type='revolute'>
          <pose frame=''>0 0 0 0 -0 0</pose>
          <parent>chassis</parent>
          <child>steering_wheel</child>
          <axis>
            <xyz>-1 0 0.84365</xyz>
            <limit>
              <lower>-3.14</lower>
              <upper>3.14</upper>
            </limit>
            <dynamics>
              <damping>1</damping>
              <spring_reference>0</spring_reference>
              <spring_stiffness>0</spring_stiffness>
            </dynamics>
            <use_parent_model_frame>1</use_parent_model_frame>
          </axis>
          <physics>
            <ode>
              <cfm_damping>1</cfm_damping>
              <limit>
                <cfm>0</cfm>
                <erp>0.2</erp>
              </limit>
            </ode>
          </physics>
        </joint>
        <joint name='hand_brake_joint' type='revolute'>
          <parent>chassis</parent>
          <child>hand_brake</child>
          <axis>
            <xyz>0 -1 0</xyz>
            <limit>
              <lower>0</lower>
              <upper>0.6</upper>
            </limit>
            <dynamics>
              <damping>1</damping>
              <spring_reference>0</spring_reference>
              <spring_stiffness>0</spring_stiffness>
            </dynamics>
            <use_parent_model_frame>1</use_parent_model_frame>
          </axis>
          <physics>
            <ode>
              <cfm_damping>1</cfm_damping>
              <limit>
                <cfm>0</cfm>
                <erp>0.2</erp>
              </limit>
            </ode>
          </physics>
        </joint>
        <joint name='FNR_switch_joint' type='revolute'>
          <parent>chassis</parent>
          <child>FNR_switch</child>
          <axis>
            <xyz>0 -1 0</xyz>
            <limit>
              <lower>-0.3</lower>
              <upper>0.3</upper>
            </limit>
            <dynamics>
              <damping>0.01</damping>
              <spring_reference>0</spring_reference>
              <spring_stiffness>0</spring_stiffness>
            </dynamics>
            <use_parent_model_frame>1</use_parent_model_frame>
          </axis>
          <physics>
            <ode>
              <cfm_damping>1</cfm_damping>
              <limit>
                <cfm>0</cfm>
                <erp>0.2</erp>
              </limit>
            </ode>
          </physics>
        </joint>
        <pose frame=''>-7.25239 3.84071 0 0 -0 0</pose>
      </model>
      <static>1</static>
      <allow_auto_disable>1</allow_auto_disable>
      <pose frame=''>-2.61849 -1.94375 0 0 -0 0</pose>
    </model>
  </world>
</sdf>
